Traceback (most recent call last):
  File "/usr/local/python/3.10.13/lib/python3.10/site-packages/jupyter_cache/executors/utils.py", line 58, in single_nb_execution
    executenb(
  File "/home/codespace/.local/lib/python3.10/site-packages/nbclient/client.py", line 1314, in execute
    return NotebookClient(nb=nb, resources=resources, km=km, **kwargs).execute()
  File "/home/codespace/.local/lib/python3.10/site-packages/jupyter_core/utils/__init__.py", line 165, in wrapped
    return loop.run_until_complete(inner)
  File "/usr/local/python/3.10.13/lib/python3.10/asyncio/base_events.py", line 649, in run_until_complete
    return future.result()
  File "/home/codespace/.local/lib/python3.10/site-packages/nbclient/client.py", line 709, in async_execute
    await self.async_execute_cell(
  File "/home/codespace/.local/lib/python3.10/site-packages/nbclient/client.py", line 1062, in async_execute_cell
    await self._check_raise_for_error(cell, cell_index, exec_reply)
  File "/home/codespace/.local/lib/python3.10/site-packages/nbclient/client.py", line 918, in _check_raise_for_error
    raise CellExecutionError.from_cell_and_msg(cell, exec_reply_content)
nbclient.exceptions.CellExecutionError: An error occurred while executing the following cell:
------------------
A= [[2,1],
    [3,1]]

B= [[2,1,2],
    [3,1,1]]

B.shape
------------------


[0;31m---------------------------------------------------------------------------[0m
[0;31mAttributeError[0m                            Traceback (most recent call last)
Cell [0;32mIn[2], line 7[0m
[1;32m      1[0m A[38;5;241m=[39m [[[38;5;241m2[39m,[38;5;241m1[39m],
[1;32m      2[0m     [[38;5;241m3[39m,[38;5;241m1[39m]]
[1;32m      4[0m B[38;5;241m=[39m [[[38;5;241m2[39m,[38;5;241m1[39m,[38;5;241m2[39m],
[1;32m      5[0m     [[38;5;241m3[39m,[38;5;241m1[39m,[38;5;241m1[39m]]
[0;32m----> 7[0m [43mB[49m[38;5;241;43m.[39;49m[43mshape[49m

[0;31mAttributeError[0m: 'list' object has no attribute 'shape'

